[ 2023-07-29 16:51:44,618 ] 187 werkzeug - INFO - [31m[1mWARNING: This is a development server. Do not use it in a production deployment. Use a production WSGI server instead.[0m
 * Running on all addresses (0.0.0.0)
 * Running on http://127.0.0.1:5000
 * Running on http://192.168.1.6:5000
[ 2023-07-29 16:51:44,619 ] 187 werkzeug - INFO - [33mPress CTRL+C to quit[0m
[ 2023-07-29 16:52:01,878 ] 187 werkzeug - INFO - 127.0.0.1 - - [29/Jul/2023 16:52:01] "GET / HTTP/1.1" 200 -
[ 2023-07-29 16:52:07,779 ] 187 werkzeug - INFO - 127.0.0.1 - - [29/Jul/2023 16:52:07] "GET /predictdata HTTP/1.1" 200 -
[ 2023-07-29 16:52:32,154 ] 1414 app - ERROR - Exception on /predictdata [POST]
Traceback (most recent call last):
  File "C:\Users\91807\Computer\Internship projects\Insurance Premium\src\pipeline\predict_pipeline.py", line 48, in get_data_as_data_frame
    "children":[self.children],
AttributeError: 'CustomData' object has no attribute 'children'

During handling of the above exception, another exception occurred:

Traceback (most recent call last):
  File "C:\Users\91807\Computer\Internship projects\Insurance Premium\insurance\lib\site-packages\flask\app.py", line 2190, in wsgi_app
    response = self.full_dispatch_request()
  File "C:\Users\91807\Computer\Internship projects\Insurance Premium\insurance\lib\site-packages\flask\app.py", line 1486, in full_dispatch_request
    rv = self.handle_user_exception(e)
  File "C:\Users\91807\Computer\Internship projects\Insurance Premium\insurance\lib\site-packages\flask\app.py", line 1484, in full_dispatch_request
    rv = self.dispatch_request()
  File "C:\Users\91807\Computer\Internship projects\Insurance Premium\insurance\lib\site-packages\flask\app.py", line 1469, in dispatch_request
    return self.ensure_sync(self.view_functions[rule.endpoint])(**view_args)
  File "app.py", line 31, in predict_datapoint
    pred_df=data.get_data_as_data_frame()
  File "C:\Users\91807\Computer\Internship projects\Insurance Premium\src\pipeline\predict_pipeline.py", line 55, in get_data_as_data_frame
    raise CustomException(e, sys)
src.exception.CustomException: Error occured in python script name [C:\Users\91807\Computer\Internship projects\Insurance Premium\src\pipeline\predict_pipeline.py] line number [48] error message ['CustomData' object has no attribute 'children']
[ 2023-07-29 16:52:32,168 ] 187 werkzeug - INFO - 127.0.0.1 - - [29/Jul/2023 16:52:32] "[35m[1mPOST /predictdata HTTP/1.1[0m" 500 -
[ 2023-07-29 16:52:34,375 ] 187 werkzeug - INFO - 127.0.0.1 - - [29/Jul/2023 16:52:34] "GET /predictdata HTTP/1.1" 200 -
